2025-01-08 14:16:32,241 INFO    MainThread:26216 [wandb_setup.py:_flush():68] Current SDK version is 0.19.2
2025-01-08 14:16:32,241 INFO    MainThread:26216 [wandb_setup.py:_flush():68] Configure stats pid to 26216
2025-01-08 14:16:32,241 INFO    MainThread:26216 [wandb_setup.py:_flush():68] Loading settings from C:\Users\melsh\.config\wandb\settings
2025-01-08 14:16:32,241 INFO    MainThread:26216 [wandb_setup.py:_flush():68] Loading settings from C:\Users\melsh\Y2B-2023-OT2_Twin\wandb\settings
2025-01-08 14:16:32,242 INFO    MainThread:26216 [wandb_setup.py:_flush():68] Loading settings from environment variables
2025-01-08 14:16:32,242 INFO    MainThread:26216 [wandb_init.py:_log_setup():523] Logging user logs to C:\Users\melsh\Y2B-2023-OT2_Twin\wandb\run-20250108_141632-ioxbadn6\logs\debug.log
2025-01-08 14:16:32,243 INFO    MainThread:26216 [wandb_init.py:_log_setup():524] Logging internal logs to C:\Users\melsh\Y2B-2023-OT2_Twin\wandb\run-20250108_141632-ioxbadn6\logs\debug-internal.log
2025-01-08 14:16:32,243 INFO    MainThread:26216 [wandb_init.py:init():641] calling init triggers
2025-01-08 14:16:32,243 INFO    MainThread:26216 [wandb_init.py:init():647] wandb.init called with sweep_config: {}
config: {}
2025-01-08 14:16:32,243 INFO    MainThread:26216 [wandb_init.py:init():674] starting backend
2025-01-08 14:16:32,602 INFO    MainThread:26216 [wandb_init.py:init():678] sending inform_init request
2025-01-08 14:16:32,607 INFO    MainThread:26216 [backend.py:_multiprocessing_setup():104] multiprocessing start_methods=spawn, using: spawn
2025-01-08 14:16:32,607 INFO    MainThread:26216 [wandb_init.py:init():693] backend started and connected
2025-01-08 14:16:32,608 INFO    MainThread:26216 [wandb_init.py:init():786] updated telemetry
2025-01-08 14:16:32,644 INFO    MainThread:26216 [wandb_init.py:init():818] communicating run to backend with 90.0 second timeout
2025-01-08 14:16:33,853 ERROR   MainThread:26216 [wandb_init.py:init():845] encountered error: failed to upsert bucket: returned error 401 Unauthorized: {"errors":[{"message":"user is not logged in","path":["upsertBucket"],"extensions":{"code":"PERMISSION_ERROR"}}],"data":{"upsertBucket":null}}
2025-01-08 14:16:33,853 ERROR   MainThread:26216 [wandb_init.py:init():1299] error in wandb.init()
Traceback (most recent call last):
  File "C:\Users\melsh\anaconda3\envs\Y2B\lib\site-packages\wandb\sdk\wandb_init.py", line 1289, in init
    return wi.init()
  File "C:\Users\melsh\anaconda3\envs\Y2B\lib\site-packages\wandb\sdk\wandb_init.py", line 851, in init
    raise error
wandb.errors.errors.CommError: failed to upsert bucket: returned error 401 Unauthorized: {"errors":[{"message":"user is not logged in","path":["upsertBucket"],"extensions":{"code":"PERMISSION_ERROR"}}],"data":{"upsertBucket":null}}
2025-01-08 14:16:33,864 WARNING MsgRouterThr:26216 [router.py:message_loop():75] message_loop has been closed
