2025-01-08 14:02:02,761 INFO    MainThread:25496 [wandb_setup.py:_flush():68] Current SDK version is 0.19.0
2025-01-08 14:02:02,761 INFO    MainThread:25496 [wandb_setup.py:_flush():68] Configure stats pid to 25496
2025-01-08 14:02:02,761 INFO    MainThread:25496 [wandb_setup.py:_flush():68] Loading settings from C:\Users\melsh\.config\wandb\settings
2025-01-08 14:02:02,761 INFO    MainThread:25496 [wandb_setup.py:_flush():68] Loading settings from C:\Users\melsh\Y2B-2023-OT2_Twin\wandb\settings
2025-01-08 14:02:02,761 INFO    MainThread:25496 [wandb_setup.py:_flush():68] Loading settings from environment variables
2025-01-08 14:02:02,761 INFO    MainThread:25496 [wandb_init.py:_log_setup():528] Logging user logs to C:\Users\melsh\Y2B-2023-OT2_Twin\wandb\run-20250108_140202-gv36v0f8\logs\debug.log
2025-01-08 14:02:02,761 INFO    MainThread:25496 [wandb_init.py:_log_setup():529] Logging internal logs to C:\Users\melsh\Y2B-2023-OT2_Twin\wandb\run-20250108_140202-gv36v0f8\logs\debug-internal.log
2025-01-08 14:02:02,763 INFO    MainThread:25496 [wandb_init.py:init():639] calling init triggers
2025-01-08 14:02:02,763 INFO    MainThread:25496 [wandb_init.py:init():645] wandb.init called with sweep_config: {}
config: {}
2025-01-08 14:02:02,763 INFO    MainThread:25496 [wandb_init.py:init():688] starting backend
2025-01-08 14:02:02,763 INFO    MainThread:25496 [wandb_init.py:init():692] sending inform_init request
2025-01-08 14:02:02,770 INFO    MainThread:25496 [backend.py:_multiprocessing_setup():104] multiprocessing start_methods=spawn, using: spawn
2025-01-08 14:02:02,771 INFO    MainThread:25496 [wandb_init.py:init():705] backend started and connected
2025-01-08 14:02:02,771 INFO    MainThread:25496 [wandb_init.py:init():798] updated telemetry
2025-01-08 14:02:02,821 INFO    MainThread:25496 [wandb_init.py:init():830] communicating run to backend with 90.0 second timeout
2025-01-08 14:02:03,640 ERROR   MainThread:25496 [wandb_init.py:init():857] encountered error: failed to upsert bucket: returned error 401 Unauthorized: {"errors":[{"message":"user is not logged in","path":["upsertBucket"],"extensions":{"code":"PERMISSION_ERROR"}}],"data":{"upsertBucket":null}}
2025-01-08 14:02:03,640 ERROR   MainThread:25496 [wandb_init.py:init():1315] error in wandb.init()
Traceback (most recent call last):
  File "C:\Users\melsh\anaconda3\envs\Y2B\lib\site-packages\wandb\sdk\wandb_init.py", line 1305, in init
    return wi.init()
  File "C:\Users\melsh\anaconda3\envs\Y2B\lib\site-packages\wandb\sdk\wandb_init.py", line 863, in init
    raise error
wandb.errors.errors.CommError: failed to upsert bucket: returned error 401 Unauthorized: {"errors":[{"message":"user is not logged in","path":["upsertBucket"],"extensions":{"code":"PERMISSION_ERROR"}}],"data":{"upsertBucket":null}}
2025-01-08 14:02:03,654 WARNING MsgRouterThr:25496 [router.py:message_loop():75] message_loop has been closed
